Workbook

Sheet Instructions
A2: 0 | B2: Project Storm - Model Map, Method & Instructions
B4: How this model is built
B6: Assumptions | C6: Every input in one place. Blue cells are hardcoded; yellow cells are the levers worth flexing.
B7: Calcs | C7: Indices, the merit-order power price stack, revenue, opex, working capital, the senior debt schedule and the tax computation.
B8: Output | C8: P&L, cash flow, the valuation, the balance sheet and the sources & uses at close. Deliberately kept free of workings.
B9: Analysis | C9: The headline results and each supporting analysis (downside, exit, hedging, tax cap, sub-debt), with full workings alongside.
B10: Sensitivities | C10: The tables behind the recommendation, including the PPA analysis.
B13: Conventions
B14: Blue text | C14: Hardcoded input or scenario lever
B15: Black text | C15: Formula calculated on the same sheet
B16: Green text | C16: Link to another sheet
B17: Yellow fill | C17: Key assumption or solved lever
B18: Units | C18: All monetary amounts are in £'000 unless the unit column says otherwise. Prices are £/MWh, production is GWh, so GWh x £/MWh gives £'000 directly.
B20: The two solved cells
B21: Calcs!E105:P105 | C21: The sculpted senior principal profile. Debt size, the interest it bears and the tax it shelters are mutually dependent, so this profile is solved outside the sheet and entered as an input. Calcs!D100 proves the DSCR is a constant 1.30x and Calcs!D118 proves the amount drawn equals the amount the sizing test supports.
B23: Analysis!D131 | C23: The subordinated loan, solved the same way. Analysis!D165 is the check.
B25: Checks that must all read nil
B26: Output!E86:S86 | C26: Balance sheet balances in every year
B27: Output!D101 | C27: Sources equal uses at close
B28: Calcs!D118 | C28: Senior debt drawn equals the debt the sizing test supports
B29: Analysis!D165 | C29: Subordinated loan drawn equals the amount 1.20x DSCR supports
B31: Key observations
B32: - | C32: Electricity demand grows at 0.25% a year to 2015 and 0.5% thereafter (Assumptions row 23). CCGT keeps ample spare capacity above demand in every year, so the clearing plant is robust to the demand path.
B34: - | C34: The merit order flips in 2020: coal becomes dearer than CCGT, so coal sets the price for two years and the curve has a hump. This is why the stack has to be ranked dynamically rather than assumed.
B36: - | C36: Senior debt is capped by the 1.30x DSCR test at £51.2m, not by the 85% of fixed assets test, which would allow £57.4m. The gearing that results is 84% of enterprise value - high, and the reason the equity return is so sensitive to price.
B38: - | C38: The 30% interest deductibility cap never binds at this leverage, so it costs nothing in the base case.

Sheet Assumptions
A2: =Instructions!A2+1 -> 1 | B2: Project Storm - Assumptions
B4: Period End | D4: 41274 | E4: =EOMONTH(D4,year_months) -> 41639 | F4: =EOMONTH(E4,year_months) -> 42004 | G4: =EOMONTH(F4,year_months) -> 42369 | H4: =EOMONTH(G4,year_months) -> 42735 | I4: =EOMONTH(H4,year_months) -> 43100 | J4: =EOMONTH(I4,year_months) -> 43465 | K4: =EOMONTH(J4,year_months) -> 43830 | L4: =EOMONTH(K4,year_months) -> 44196 | ... S4: =EOMONTH(R4,year_months) -> 46752
B5: Calendar Year | D5: =YEAR(D4) -> 2012 | E5: =YEAR(E4) -> 2013 | F5: =YEAR(F4) -> 2014 | G5: =YEAR(G4) -> 2015 | H5: =YEAR(H4) -> 2016 | I5: =YEAR(I4) -> 2017 | J5: =YEAR(J4) -> 2018 | K5: =YEAR(K4) -> 2019 | ... S5: =YEAR(S4) -> 2027
B6: Model Year | D6: 0 | E6: =D6+1 -> 1 | F6: =E6+1 -> 2 | G6: =F6+1 -> 3 | H6: =G6+1 -> 4 | I6: =H6+1 -> 5 | J6: =I6+1 -> 6 | K6: =J6+1 -> 7 | L6: =K6+1 -> 8 | ... S6: =R6+1 -> 15
A8: =MAX($A$2:A7)+0.01 -> 1.01 | B8: General
B10: Hours in year | C10: [hours] | D10: 8760
B11: Months in Year | C11: [months] | D11: 12
A14: =MAX($A$2:A13)+0.01 -> 1.02 | B14: Economics
B16: CPI | C16: [%] | D16: 0.025 | E16: 0.025 | F16: 0.025 | G16: 0.025 | H16: 0.02 | I16: 0.02 | J16: 0.02 | K16: 0.02 | L16: 0.02 | M16: 0.02 | N16: 0.02 | O16: 0.02 | P16: 0.02 | Q16: 0.02 | R16: 0.02 | S16: 0.02 | U16: 2.5% to 2015 inclusive, 2.0% thereafter
B17: Libor | C17: [%] | D17: 0.00939 | E17: 0.0086301431 | F17: 0.0094860561 | G17: 0.012707946 | H17: 0.016694652 | I17: 0.020548944 | J17: 0.023015624 | K17: 0.024223962 | L17: 0.025343402 | M17: 0.025947203 | N17: 0.027337059 | O17: 0.027657667 | P17: 0.027657667 | Q17: 0.026492746 | R17: 0.026492746 | S17: 0.026492746 | U17: LIBOR curve as input; no interest income assumed
A20: =MAX($A$2:A19)+0.01 -> 1.03 | B20: Electricity Market
B22: Demand | C22: [TWh] | D22: 320 | E22: =D22*(1+E23) -> 320.8 | F22: =E22*(1+F23) -> 321.602 | G22: =F22*(1+G23) -> 322.406 | H22: =G22*(1+H23) -> 324.01804 | I22: =H22*(1+I23) -> 325.63813 | J22: =I22*(1+J23) -> 327.26632 | K22: =J22*(1+K23) -> 328.90265 | L22: =K22*(1+L23) -> 330.54716 | ... S22: =R22*(1+S23) -> 342.2913 | T22: << | U22: Demand grows at +0.25% p.a. to 2015 and +0.5% thereafter, driven by row 23.
B23: Demand Growth | C23: [%] | E23: 0.0025 | F23: 0.0025 | G23: 0.0025 | H23: 0.005 | I23: 0.005 | J23: 0.005 | K23: 0.005 | L23: 0.005 | M23: 0.005 | N23: 0.005 | O23: 0.005 | P23: 0.005 | Q23: 0.005 | R23: 0.005 | S23: 0.005
B24: Supply
B26: Average Installed Capacity Forecast
B27: Coal | C27: [GW] | D27: 35 | E27: 35 | F27: 35 | G27: 32.5 | H27: 30 | I27: 27.5 | J27: 25 | K27: 22.5 | L27: 20 | M27: 20 | N27: 20 | O27: 20 | P27: 15 | Q27: 15 | R27: 10 | S27: 0
B28: CCGT | C28: [GW] | D28: 55 | E28: 55 | F28: 55 | G28: 55 | H28: 55 | I28: 55 | J28: 55 | K28: 55 | L28: 57 | M28: 59 | N28: 61 | O28: 61 | P28: 61 | Q28: 61 | R28: 61 | S28: 61
B29: Renewables (incl. Hydro) | C29: [GW] | D29: 15 | E29: 15.45 | F29: 15.9135 | G29: 16.390905 | H29: 16.882632 | I29: 17.389111 | J29: 17.910784 | K29: 18.448108 | L29: 19.001551 | M29: 19.571598 | N29: 20.158746 | O29: 20.763508 | P29: 21.386413 | Q29: 22.028006 | R29: 22.688846 | S29: 23.369511
B31: Weighted Avg Capacity Factor
B32: =B27 -> Coal | C32: [%] | D32: 0.35 | E32: 0.34653465 | F32: 0.34310362 | G32: 0.33970655 | H32: 0.33634312 | I32: 0.33301299 | J32: 0.32971583 | K32: 0.3 | L32: 0.3 | M32: 0.3 | N32: 0.3 | O32: 0.3 | P32: 0.3 | Q32: 0.3 | R32: 0.3 | S32: 0.3
B33: =B28 -> CCGT | C33: [%] | D33: 0.5 | E33: 0.505 | F33: 0.51005 | G33: 0.5151505 | H33: 0.52030201 | I33: 0.52550503 | J33: 0.53076008 | K33: 0.53606768 | L33: 0.54142835 | M33: 0.54684264 | N33: 0.55231106 | O33: 0.55783417 | P33: 0.56341252 | Q33: 0.56904664 | R33: 0.57473711 | S33: 0.58048448
B34: =B29 -> Renewables (incl. Hydro) | C34: [%] | D34: 0.2 | E34: =D34*1.015 -> 0.203 | F34: =E34*1.015 -> 0.206045 | G34: =F34*1.015 -> 0.20913567 | H34: =G34*1.015 -> 0.21227271 | I34: =H34*1.015 -> 0.2154568 | J34: =I34*1.015 -> 0.21868865 | K34: =J34*1.015 -> 0.22196898 | L34: =K34*1.015 -> 0.22529852 | ... S34: =R34*1.015 -> 0.25004641
B36: Weighted Avg Marginal Cost | C36: [real - 2012]
B37: =B27 -> Coal | C37: [£/MWh - Real] | D37: 35 | E37: 35.35 | F37: 36.057 | G37: 37.13871 | H37: 38.624258 | I37: 40.555471 | J37: 42.9888 | K37: 45.998016 | L37: 49.677857 | M37: 50.671414 | N37: 51.684842 | O37: 52.718539 | P37: 53.77291 | Q37: 54.848368 | R37: 55.945335 | S37: 57.064242
B38: =B28 -> CCGT | C38: [£/MWh - Real] | D38: 55 | E38: 54.726368 | F38: 54.184523 | G38: 53.383766 | H38: 52.337026 | I38: 51.060513 | J38: 49.573314 | K38: 47.896921 | L38: 46.054732 | M38: 44.071514 | N38: 41.97287 | O38: 39.784711 | P38: 37.532747 | Q38: 35.242016 | R38: 32.936463 | S38: 30.63857
B39: =B29 -> Renewables (incl. Hydro) | C39: [£/MWh - Real] | D39: 5 | E39: 5 | F39: 5 | G39: 5 | H39: 5 | I39: 5 | J39: 5 | K39: 5 | L39: 5 | M39: 5 | N39: 5 | O39: 5 | P39: 5 | Q39: 5 | R39: 5 | S39: 5
B41: Hint: supply is always equal to demand; if possible try to make the pricing calculation dynamic (you may need to rank the supply)
A44: =MAX($A$2:A43)+0.01 -> 1.04 | B44: Operating Assumptions
B46: Generation
B47: Installed Capacity | C47: [MW] | D47: 50
B48: Load Factor - P75 | C48: [hours] | D48: 2500
B49: Load Factor - P90 | C49: [hours] | D49: 2350
B50: Production Case (1=P75, 2=P90, 3=P90 10y then P75) | C50: [#] | D50: 1
B51: Operations Start Date | C51: [date] | D51: 39448
B52: Residual Accounting & Economic Life | C52: [years] | D52: 15
B54: Regulated Subsidy
B55: Subsidy Price - 2012 | C55: [£/MWh] | D55: 40
B56: Subsidy Escalation (CPI - 1.5%) | C56: [%] | E56: =MAX(E16-E57,0) -> 0.01 | F56: =MAX(F16-F57,0) -> 0.01 | G56: =MAX(G16-G57,0) -> 0.01 | H56: =MAX(H16-H57,0) -> 0.005 | I56: =MAX(I16-I57,0) -> 0.005 | J56: =MAX(J16-J57,0) -> 0.005 | K56: =MAX(K16-K57,0) -> 0.005 | L56: =MAX(L16-L57,0) -> 0.005 | ... S56: =MAX(S16-S57,0) -> 0.005
B57: Subsidy Escalation Discount to CPI | C57: [%] | D57: 0.015 | E57: 0.015 | F57: 0.015 | G57: 0.015 | H57: 0.015 | I57: 0.015 | J57: 0.015 | K57: 0.015 | L57: 0.015 | M57: 0.015 | N57: 0.015 | O57: 0.015 | P57: 0.015 | Q57: 0.015 | R57: 0.015 | S57: 0.015
B58: Subsidy Tenor from Operations Start | C58: [years] | D58: 15
...

Sheet Calcs
A2: =Assumptions!A2+1 -> 2 | B2: Project Storm - Calculations
B4: Period End | D4: =timeline -> 41274 | E4: =timeline -> 41639 | F4: =timeline -> 42004 | G4: =timeline -> 42369 | H4: =timeline -> 42735 | I4: =timeline -> 43100 | J4: =timeline -> 43465 | K4: =timeline -> 43830 | ... S4: =timeline -> 46752
B5: Calendar Year | D5: =YEAR(D4) -> 2012 | E5: =YEAR(E4) -> 2013 | F5: =YEAR(F4) -> 2014 | G5: =YEAR(G4) -> 2015 | H5: =YEAR(H4) -> 2016 | I5: =YEAR(I4) -> 2017 | J5: =YEAR(J4) -> 2018 | K5: =YEAR(K4) -> 2019 | ... S5: =YEAR(S4) -> 2027
B6: Model Year | D6: 0 | E6: =D6+1 -> 1 | F6: =E6+1 -> 2 | G6: =F6+1 -> 3 | H6: =G6+1 -> 4 | I6: =H6+1 -> 5 | J6: =I6+1 -> 6 | K6: =J6+1 -> 7 | L6: =K6+1 -> 8 | ... S6: =R6+1 -> 15
B8: CPI Index | C8: [x] | D8: 1 | E8: =D8*(1+Assumptions!E16) -> 1.025 | F8: =E8*(1+Assumptions!F16) -> 1.050625 | G8: =F8*(1+Assumptions!G16) -> 1.0768906 | H8: =G8*(1+Assumptions!H16) -> 1.0984284 | I8: =H8*(1+Assumptions!I16) -> 1.120397 | J8: =I8*(1+Assumptions!J16) -> 1.1428049 | K8: =J8*(1+Assumptions!K16) -> 1.165661 | L8: =K8*(1+Assumptions!L16) -> 1.1889743 | ... S8: =R8*(1+Assumptions!S16) -> 1.3657577
B9: Cost Index (CPI + 0.25%) | C9: [x] | D9: 1 | E9: =D9*(1+Assumptions!E65) -> 1.0275 | F9: =E9*(1+Assumptions!F65) -> 1.0557562 | G9: =F9*(1+Assumptions!G65) -> 1.0847895 | H9: =G9*(1+Assumptions!H65) -> 1.1091973 | I9: =H9*(1+Assumptions!I65) -> 1.1341543 | J9: =I9*(1+Assumptions!J65) -> 1.1596727 | K9: =J9*(1+Assumptions!K65) -> 1.1857654 | L9: =K9*(1+Assumptions!L65) -> 1.2124451 | ... S9: =R9*(1+Assumptions!S65) -> 1.4167894
B10: Subsidy Index (CPI - 1.5%) | C10: [x] | D10: 1 | E10: =D10*(1+Assumptions!E56) -> 1.01 | F10: =E10*(1+Assumptions!F56) -> 1.0201 | G10: =F10*(1+Assumptions!G56) -> 1.030301 | H10: =G10*(1+Assumptions!H56) -> 1.0354525 | I10: =H10*(1+Assumptions!I56) -> 1.0406298 | J10: =I10*(1+Assumptions!J56) -> 1.0458329 | K10: =J10*(1+Assumptions!K56) -> 1.0510621 | L10: =K10*(1+Assumptions!L56) -> 1.0563174 | ... S10: =R10*(1+Assumptions!S56) -> 1.0938477
A11: =MAX($A$2:A9)+0.01 -> 2.01 | B11: Revenues
B13: Production
B15: P75 | C15: [GWh] | D15: =Assumptions!$D$47*Assumptions!$D$48/1000 -> 125 | E15: =Assumptions!$D$47*Assumptions!$D$48/1000 -> 125 | F15: =Assumptions!$D$47*Assumptions!$D$48/1000 -> 125 | G15: =Assumptions!$D$47*Assumptions!$D$48/1000 -> 125 | H15: =Assumptions!$D$47*Assumptions!$D$48/1000 -> 125 | I15: =Assumptions!$D$47*Assumptions!$D$48/1000 -> 125 | J15: =Assumptions!$D$47*Assumptions!$D$48/1000 -> 125 | K15: =Assumptions!$D$47*Assumptions!$D$48/1000 -> 125 | ... S15: =Assumptions!$D$47*Assumptions!$D$48/1000 -> 125
B16: P90 | C16: [GWh] | D16: =Assumptions!$D$47*Assumptions!$D$49/1000 -> 117.5 | E16: =Assumptions!$D$47*Assumptions!$D$49/1000 -> 117.5 | F16: =Assumptions!$D$47*Assumptions!$D$49/1000 -> 117.5 | G16: =Assumptions!$D$47*Assumptions!$D$49/1000 -> 117.5 | H16: =Assumptions!$D$47*Assumptions!$D$49/1000 -> 117.5 | I16: =Assumptions!$D$47*Assumptions!$D$49/1000 -> 117.5 | J16: =Assumptions!$D$47*Assumptions!$D$49/1000 -> 117.5 | K16: =Assumptions!$D$47*Assumptions!$D$49/1000 -> 117.5 | ... S16: =Assumptions!$D$47*Assumptions!$D$49/1000 -> 117.5
B17: Selected Scenario | C17: [GWh] | D17: =IF(Assumptions!$D$50=1,D15,IF(Assumptions!$D$50=2,D16,IF(D$5<=$D$5+10,D16,D15))) -> 125 | E17: =IF(Assumptions!$D$50=1,E15,IF(Assumptions!$D$50=2,E16,IF(E$5<=$D$5+10,E16,E15))) -> 125 | F17: =IF(Assumptions!$D$50=1,F15,IF(Assumptions!$D$50=2,F16,IF(F$5<=$D$5+10,F16,F15))) -> 125 | G17: =IF(Assumptions!$D$50=1,G15,IF(Assumptions!$D$50=2,G16,IF(G$5<=$D$5+10,G16,G15))) -> 125 | H17: =IF(Assumptions!$D$50=1,H15,IF(Assumptions!$D$50=2,H16,IF(H$5<=$D$5+10,H16,H15))) -> 125 | I17: =IF(Assumptions!$D$50=1,I15,IF(Assumptions!$D$50=2,I16,IF(I$5<=$D$5+10,I16,I15))) -> 125 | J17: =IF(Assumptions!$D$50=1,J15,IF(Assumptions!$D$50=2,J16,IF(J$5<=$D$5+10,J16,J15))) -> 125 | K17: =IF(Assumptions!$D$50=1,K15,IF(Assumptions!$D$50=2,K16,IF(K$5<=$D$5+10,K16,K15))) -> 125 | ... S17: =IF(Assumptions!$D$50=1,S15,IF(Assumptions!$D$50=2,S16,IF(S$5<=$D$5+10,S16,S15))) -> 125 | U17: Case 3 = P90 for the first 10 years (2013-22), P75 from 2023. 2012 shown at P75 for reference only - the buyer owns no 2012 economics.
B21: Power Prices
B23: Demand Index | C23: [x] | D23: =D24/$D$24 -> 1 | E23: =E24/$D$24 -> 1.0025 | F23: =F24/$D$24 -> 1.0050063 | G23: =G24/$D$24 -> 1.0075188 | H23: =H24/$D$24 -> 1.0125564 | I23: =I24/$D$24 -> 1.0176191 | J23: =J24/$D$24 -> 1.0227072 | K23: =K24/$D$24 -> 1.0278208 | ... S23: =S24/$D$24 -> 1.0696603
B24: Annual Demand | C24: [TWh] | D24: =Assumptions!D22 -> 320 | E24: =Assumptions!E22 -> 320.8 | F24: =Assumptions!F22 -> 321.602 | G24: =Assumptions!G22 -> 322.406 | H24: =Assumptions!H22 -> 324.01804 | I24: =Assumptions!I22 -> 325.63813 | J24: =Assumptions!J22 -> 327.26632 | K24: =Assumptions!K22 -> 328.90265 | ... S24: =Assumptions!S22 -> 342.2913
B26: Generation by Technology | C26: [TWh]
B27: Coal | C27: [TWh] | D27: =Assumptions!D27*Assumptions!D32*Assumptions!$D$10/1000 -> 107.31 | E27: =Assumptions!E27*Assumptions!E32*Assumptions!$D$10/1000 -> 106.24752 | F27: =Assumptions!F27*Assumptions!F32*Assumptions!$D$10/1000 -> 105.19557 | G27: =Assumptions!G27*Assumptions!G32*Assumptions!$D$10/1000 -> 96.714455 | H27: =Assumptions!H27*Assumptions!H32*Assumptions!$D$10/1000 -> 88.390972 | I27: =Assumptions!I27*Assumptions!I32*Assumptions!$D$10/1000 -> 80.222829 | J27: =Assumptions!J27*Assumptions!J32*Assumptions!$D$10/1000 -> 72.207767 | K27: =Assumptions!K27*Assumptions!K32*Assumptions!$D$10/1000 -> 59.13 | ... S27: =Assumptions!S27*Assumptions!S32*Assumptions!$D$10/1000 -> 0
B28: CCGT | C28: [TWh] | D28: =Assumptions!D28*Assumptions!D33*Assumptions!$D$10/1000 -> 240.9 | E28: =Assumptions!E28*Assumptions!E33*Assumptions!$D$10/1000 -> 243.309 | F28: =Assumptions!F28*Assumptions!F33*Assumptions!$D$10/1000 -> 245.74209 | G28: =Assumptions!G28*Assumptions!G33*Assumptions!$D$10/1000 -> 248.19951 | H28: =Assumptions!H28*Assumptions!H33*Assumptions!$D$10/1000 -> 250.68151 | I28: =Assumptions!I28*Assumptions!I33*Assumptions!$D$10/1000 -> 253.18832 | J28: =Assumptions!J28*Assumptions!J33*Assumptions!$D$10/1000 -> 255.7202 | K28: =Assumptions!K28*Assumptions!K33*Assumptions!$D$10/1000 -> 258.27741 | ... S28: =Assumptions!S28*Assumptions!S33*Assumptions!$D$10/1000 -> 310.18769
B29: Renewables | C29: [TWh] | D29: =Assumptions!D29*Assumptions!D34*Assumptions!$D$10/1000 -> 26.28 | E29: =Assumptions!E29*Assumptions!E34*Assumptions!$D$10/1000 -> 27.474426 | F29: =Assumptions!F29*Assumptions!F34*Assumptions!$D$10/1000 -> 28.723139 | G29: =Assumptions!G29*Assumptions!G34*Assumptions!$D$10/1000 -> 30.028605 | H29: =Assumptions!H29*Assumptions!H34*Assumptions!$D$10/1000 -> 31.393405 | I29: =Assumptions!I29*Assumptions!I34*Assumptions!$D$10/1000 -> 32.820236 | J29: =Assumptions!J29*Assumptions!J34*Assumptions!$D$10/1000 -> 34.311915 | K29: =Assumptions!K29*Assumptions!K34*Assumptions!$D$10/1000 -> 35.871392 | ... S29: =Assumptions!S29*Assumptions!S34*Assumptions!$D$10/1000 -> 51.188731
B30: Total Supply Available | C30: [TWh] | D30: =SUM(D27:D29) -> 374.49 | E30: =SUM(E27:E29) -> 377.03095 | F30: =SUM(F27:F29) -> 379.6608 | G30: =SUM(G27:G29) -> 374.94257 | H30: =SUM(H27:H29) -> 370.46588 | I30: =SUM(I27:I29) -> 366.23139 | J30: =SUM(J27:J29) -> 362.23989 | K30: =SUM(K27:K29) -> 353.2788 | ... S30: =SUM(S27:S29) -> 361.37642
B31: Surplus / (Deficit) vs Demand | C31: [TWh] | D31: =D30-D24 -> 54.49 | E31: =E30-E24 -> 56.230951 | F31: =F30-F24 -> 58.058798 | G31: =G30-G24 -> 52.536567 | H31: =H30-H24 -> 46.447848 | I31: =I30-I24 -> 40.593261 | J31: =J30-J24 -> 34.973571 | K31: =K30-K24 -> 24.376151 | ... S31: =S30-S24 -> 19.085115
B33: Marginal Cost - Real 2012 | C33: [£/MWh]
B34: Coal | C34: [£/MWh] | D34: =Assumptions!D37 -> 35 | E34: =Assumptions!E37 -> 35.35 | F34: =Assumptions!F37 -> 36.057 | G34: =Assumptions!G37 -> 37.13871 | H34: =Assumptions!H37 -> 38.624258 | I34: =Assumptions!I37 -> 40.555471 | J34: =Assumptions!J37 -> 42.9888 | K34: =Assumptions!K37 -> 45.998016 | ... S34: =Assumptions!S37 -> 57.064242
B35: CCGT | C35: [£/MWh] | D35: =Assumptions!D38 -> 55 | E35: =Assumptions!E38 -> 54.726368 | F35: =Assumptions!F38 -> 54.184523 | G35: =Assumptions!G38 -> 53.383766 | H35: =Assumptions!H38 -> 52.337026 | I35: =Assumptions!I38 -> 51.060513 | J35: =Assumptions!J38 -> 49.573314 | K35: =Assumptions!K38 -> 47.896921 | ... S35: =Assumptions!S38 -> 30.63857
B36: Renewables | C36: [£/MWh] | D36: =Assumptions!D39 -> 5 | E36: =Assumptions!E39 -> 5 | F36: =Assumptions!F39 -> 5 | G36: =Assumptions!G39 -> 5 | H36: =Assumptions!H39 -> 5 | I36: =Assumptions!I39 -> 5 | J36: =Assumptions!J39 -> 5 | K36: =Assumptions!K39 -> 5 | ... S36: =Assumptions!S39 -> 5
B38: Generation Cheaper than this Plant | C38: [TWh]
B39: Coal | C39: [TWh] | D39: =SUMPRODUCT((D$34:D$36<D34)*D$27:D$29) -> 26.28 | E39: =SUMPRODUCT((E$34:E$36<E34)*E$27:E$29) -> 27.474426 | F39: =SUMPRODUCT((F$34:F$36<F34)*F$27:F$29) -> 28.723139 | G39: =SUMPRODUCT((G$34:G$36<G34)*G$27:G$29) -> 30.028605 | H39: =SUMPRODUCT((H$34:H$36<H34)*H$27:H$29) -> 31.393405 | I39: =SUMPRODUCT((I$34:I$36<I34)*I$27:I$29) -> 32.820236 | J39: =SUMPRODUCT((J$34:J$36<J34)*J$27:J$29) -> 34.311915 | K39: =SUMPRODUCT((K$34:K$36<K34)*K$27:K$29) -> 35.871392 | ... S39: =SUMPRODUCT((S$34:S$36<S34)*S$27:S$29) -> 361.37642
B40: CCGT | C40: [TWh] | D40: =SUMPRODUCT((D$34:D$36<D35)*D$27:D$29) -> 133.59 | E40: =SUMPRODUCT((E$34:E$36<E35)*E$27:E$29) -> 133.72195 | F40: =SUMPRODUCT((F$34:F$36<F35)*F$27:F$29) -> 133.91871 | G40: =SUMPRODUCT((G$34:G$36<G35)*G$27:G$29) -> 126.74306 | H40: =SUMPRODUCT((H$34:H$36<H35)*H$27:H$29) -> 119.78438 | I40: =SUMPRODUCT((I$34:I$36<I35)*I$27:I$29) -> 113.04307 | J40: =SUMPRODUCT((J$34:J$36<J35)*J$27:J$29) -> 106.51968 | K40: =SUMPRODUCT((K$34:K$36<K35)*K$27:K$29) -> 95.001392 | ... S40: =SUMPRODUCT((S$34:S$36<S35)*S$27:S$29) -> 51.188731
B41: Renewables | C41: [TWh] | D41: =SUMPRODUCT((D$34:D$36<D36)*D$27:D$29) -> 0 | E41: =SUMPRODUCT((E$34:E$36<E36)*E$27:E$29) -> 0 | F41: =SUMPRODUCT((F$34:F$36<F36)*F$27:F$29) -> 0 | G41: =SUMPRODUCT((G$34:G$36<G36)*G$27:G$29) -> 0 | H41: =SUMPRODUCT((H$34:H$36<H36)*H$27:H$29) -> 0 | I41: =SUMPRODUCT((I$34:I$36<I36)*I$27:I$29) -> 0 | J41: =SUMPRODUCT((J$34:J$36<J36)*J$27:J$29) -> 0 | K41: =SUMPRODUCT((K$34:K$36<K36)*K$27:K$29) -> 0 | ... S41: =SUMPRODUCT((S$34:S$36<S36)*S$27:S$29) -> 0
B43: Marginal Plant Flag (1 = sets the price) | C43: [#]
B44: Coal | C44: [#] | D44: =IF(AND(D39<D$24,D39+D27>=D$24),1,0) -> 0 | E44: =IF(AND(E39<E$24,E39+E27>=E$24),1,0) -> 0 | F44: =IF(AND(F39<F$24,F39+F27>=F$24),1,0) -> 0 | G44: =IF(AND(G39<G$24,G39+G27>=G$24),1,0) -> 0 | H44: =IF(AND(H39<H$24,H39+H27>=H$24),1,0) -> 0 | I44: =IF(AND(I39<I$24,I39+I27>=I$24),1,0) -> 0 | J44: =IF(AND(J39<J$24,J39+J27>=J$24),1,0) -> 0 | K44: =IF(AND(K39<K$24,K39+K27>=K$24),1,0) -> 0 | ... S44: =IF(AND(S39<S$24,S39+S27>=S$24),1,0) -> 0
B45: CCGT | C45: [#] | D45: =IF(AND(D40<D$24,D40+D28>=D$24),1,0) -> 1 | E45: =IF(AND(E40<E$24,E40+E28>=E$24),1,0) -> 1 | F45: =IF(AND(F40<F$24,F40+F28>=F$24),1,0) -> 1 | G45: =IF(AND(G40<G$24,G40+G28>=G$24),1,0) -> 1 | H45: =IF(AND(H40<H$24,H40+H28>=H$24),1,0) -> 1 | I45: =IF(AND(I40<I$24,I40+I28>=I$24),1,0) -> 1 | J45: =IF(AND(J40<J$24,J40+J28>=J$24),1,0) -> 1 | K45: =IF(AND(K40<K$24,K40+K28>=K$24),1,0) -> 1 | ... S45: =IF(AND(S40<S$24,S40+S28>=S$24),1,0) -> 1
B46: Renewables | C46: [#] | D46: =IF(AND(D41<D$24,D41+D29>=D$24),1,0) -> 0 | E46: =IF(AND(E41<E$24,E41+E29>=E$24),1,0) -> 0 | F46: =IF(AND(F41<F$24,F41+F29>=F$24),1,0) -> 0 | G46: =IF(AND(G41<G$24,G41+G29>=G$24),1,0) -> 0 | H46: =IF(AND(H41<H$24,H41+H29>=H$24),1,0) -> 0 | I46: =IF(AND(I41<I$24,I41+I29>=I$24),1,0) -> 0 | J46: =IF(AND(J41<J$24,J41+J29>=J$24),1,0) -> 0 | K46: =IF(AND(K41<K$24,K41+K29>=K$24),1,0) -> 0 | ... S46: =IF(AND(S41<S$24,S41+S29>=S$24),1,0) -> 0
B47: Marginal Technology | C47: [text] | D47: =IF(D44=1,"Coal",IF(D45=1,"CCGT","Renewables")) -> CCGT | E47: =IF(E44=1,"Coal",IF(E45=1,"CCGT","Renewables")) -> CCGT | F47: =IF(F44=1,"Coal",IF(F45=1,"CCGT","Renewables")) -> CCGT | G47: =IF(G44=1,"Coal",IF(G45=1,"CCGT","Renewables")) -> CCGT | H47: =IF(H44=1,"Coal",IF(H45=1,"CCGT","Renewables")) -> CCGT | I47: =IF(I44=1,"Coal",IF(I45=1,"CCGT","Renewables")) -> CCGT | J47: =IF(J44=1,"Coal",IF(J45=1,"CCGT","Renewables")) -> CCGT | K47: =IF(K44=1,"Coal",IF(K45=1,"CCGT","Renewables")) -> CCGT | ... S47: =IF(S44=1,"Coal",IF(S45=1,"CCGT","Renewables")) -> CCGT
B48: Marginal Cost of Marginal Plant | C48: [£/MWh real] | D48: =SUMPRODUCT(D44:D46,D34:D36) -> 55 | E48: =SUMPRODUCT(E44:E46,E34:E36) -> 54.726368 | F48: =SUMPRODUCT(F44:F46,F34:F36) -> 54.184523 | G48: =SUMPRODUCT(G44:G46,G34:G36) -> 53.383766 | H48: =SUMPRODUCT(H44:H46,H34:H36) -> 52.337026 | I48: =SUMPRODUCT(I44:I46,I34:I36) -> 51.060513 | J48: =SUMPRODUCT(J44:J46,J34:J36) -> 49.573314 | K48: =SUMPRODUCT(K44:K46,K34:K36) -> 47.896921 | ... S48: =SUMPRODUCT(S44:S46,S34:S36) -> 30.63857
B49: Applicable Electricity Price | C49: [£/MWh] | D49: =D48*D8 -> 55 | E49: =E48*E8 -> 56.094527 | F49: =F48*F8 -> 56.927614 | G49: =G48*G8 -> 57.488478 | H49: =H48*H8 -> 57.488478 | I49: =I48*I8 -> 57.208046 | J49: =J48*J8 -> 56.652628 | K49: =K48*K8 -> 55.831575 | ... S49: =S48*S8 -> 41.844863
B50: Applicable Subsidy | C50: [£/MWh] | D50: =IF(D$5<=Assumptions!$D$59,Assumptions!$D$55*D10,0) -> 40 | E50: =IF(E$5<=Assumptions!$D$59,Assumptions!$D$55*E10,0) -> 40.4 | F50: =IF(F$5<=Assumptions!$D$59,Assumptions!$D$55*F10,0) -> 40.804 | G50: =IF(G$5<=Assumptions!$D$59,Assumptions!$D$55*G10,0) -> 41.21204 | H50: =IF(H$5<=Assumptions!$D$59,Assumptions!$D$55*H10,0) -> 41.4181 | I50: =IF(I$5<=Assumptions!$D$59,Assumptions!$D$55*I10,0) -> 41.625191 | J50: =IF(J$5<=Assumptions!$D$59,Assumptions!$D$55*J10,0) -> 41.833317 | K50: =IF(K$5<=Assumptions!$D$59,Assumptions!$D$55*K10,0) -> 42.042483 | ... S50: =IF(S$5<=Assumptions!$D$59,Assumptions!$D$55*S10,0) -> 0
B52: Revenue from Electricity | C52: [£'000] | D52: =D17*D49 -> 6875 | E52: =E17*E49 -> 7011.8159 | F52: =F17*F49 -> 7115.9518 | G52: =G17*G49 -> 7186.0597 | H52: =H17*H49 -> 7186.0597 | I52: =I17*I49 -> 7151.0058 | J52: =J17*J49 -> 7081.5785 | K52: =K17*K49 -> 6978.9469 | ... S52: =S17*S49 -> 5230.6079 | U52: GWh x £/MWh = £'000, so no unit conversion is needed here.
B53: Revenue from Subsidy | C53: [£'000] | D53: =D17*D50 -> 5000 | E53: =E17*E50 -> 5050 | F53: =F17*F50 -> 5100.5 | G53: =G17*G50 -> 5151.505 | H53: =H17*H50 -> 5177.2625 | I53: =I17*I50 -> 5203.1488 | J53: =J17*J50 -> 5229.1646 | K53: =K17*K50 -> 5255.3104 | ... S53: =S17*S50 -> 0
B54: Total Revenues | C54: [£'000] | D54: =SUM(D52:D53) -> 11875 | E54: =SUM(E52:E53) -> 12061.816 | F54: =SUM(F52:F53) -> 12216.452 | G54: =SUM(G52:G53) -> 12337.565 | H54: =SUM(H52:H53) -> 12363.322 | I54: =SUM(I52:I53) -> 12354.155 | J54: =SUM(J52:J53) -> 12310.743 | K54: =SUM(K52:K53) -> 12234.257 | ... S54: =SUM(S52:S53) -> 5230.6079
...

Sheet Output
A2: =Calcs!A2+1 -> 3 | B2: Project Storm - Financial Statements & Valuation
B4: Period End | D4: =timeline -> 41274 | E4: =timeline -> 41639 | F4: =timeline -> 42004 | G4: =timeline -> 42369 | H4: =timeline -> 42735 | I4: =timeline -> 43100 | J4: =timeline -> 43465 | K4: =timeline -> 43830 | ... S4: =timeline -> 46752
B5: Calendar Year | D5: =YEAR(D4) -> 2012 | E5: =YEAR(E4) -> 2013 | F5: =YEAR(F4) -> 2014 | G5: =YEAR(G4) -> 2015 | H5: =YEAR(H4) -> 2016 | I5: =YEAR(I4) -> 2017 | J5: =YEAR(J4) -> 2018 | K5: =YEAR(K4) -> 2019 | ... S5: =YEAR(S4) -> 2027
B6: Model Year | D6: 0 | E6: =D6+1 -> 1 | F6: =E6+1 -> 2 | G6: =F6+1 -> 3 | H6: =G6+1 -> 4 | I6: =H6+1 -> 5 | J6: =I6+1 -> 6 | K6: =J6+1 -> 7 | L6: =K6+1 -> 8 | ... S6: =R6+1 -> 15
A8: =MAX($A$2:A3)+0.01 -> 3.01 | B8: Profit & Loss Account
B10: Production | C10: [GWh] | D10: =Calcs!D17 -> 125 | E10: =Calcs!E17 -> 125 | F10: =Calcs!F17 -> 125 | G10: =Calcs!G17 -> 125 | H10: =Calcs!H17 -> 125 | I10: =Calcs!I17 -> 125 | J10: =Calcs!J17 -> 125 | K10: =Calcs!K17 -> 125 | ... S10: =Calcs!S17 -> 125 | U10: 2012 revenue and EBITDA are shown for reference only - the vendor retains the economic benefit of the asset until 31-Dec-2012.
B12: Revenue from Electricity | C12: [£'000] | D12: =Calcs!D52 -> 6875 | E12: =Calcs!E52 -> 7011.8159 | F12: =Calcs!F52 -> 7115.9518 | G12: =Calcs!G52 -> 7186.0597 | H12: =Calcs!H52 -> 7186.0597 | I12: =Calcs!I52 -> 7151.0058 | J12: =Calcs!J52 -> 7081.5785 | K12: =Calcs!K52 -> 6978.9469 | ... S12: =Calcs!S52 -> 5230.6079
B13: Revenue from Subsidies | C13: [£'000] | D13: =Calcs!D53 -> 5000 | E13: =Calcs!E53 -> 5050 | F13: =Calcs!F53 -> 5100.5 | G13: =Calcs!G53 -> 5151.505 | H13: =Calcs!H53 -> 5177.2625 | I13: =Calcs!I53 -> 5203.1488 | J13: =Calcs!J53 -> 5229.1646 | K13: =Calcs!K53 -> 5255.3104 | ... S13: =Calcs!S53 -> 0
B14: Total Revenue | C14: [£'000] | D14: =SUM(D12:D13) -> 11875 | E14: =SUM(E12:E13) -> 12061.816 | F14: =SUM(F12:F13) -> 12216.452 | G14: =SUM(G12:G13) -> 12337.565 | H14: =SUM(H12:H13) -> 12363.322 | I14: =SUM(I12:I13) -> 12354.155 | J14: =SUM(J12:J13) -> 12310.743 | K14: =SUM(K12:K13) -> 12234.257 | ... S14: =SUM(S12:S13) -> 5230.6079
B16: Variable Costs | C16: [£'000] | D16: =-Calcs!D61 -> -625 | E16: =-Calcs!E61 -> -642.1875 | F16: =-Calcs!F61 -> -659.84766 | G16: =-Calcs!G61 -> -677.99347 | H16: =-Calcs!H61 -> -693.24832 | I16: =-Calcs!I61 -> -708.84641 | J16: =-Calcs!J61 -> -724.79545 | K16: =-Calcs!K61 -> -741.10335 | ... S16: =-Calcs!S61 -> -885.49336
B17: Fixed Costs | C17: [£'000] | D17: =-Calcs!D60 -> -2500 | E17: =-Calcs!E60 -> -2568.75 | F17: =-Calcs!F60 -> -2639.3906 | G17: =-Calcs!G60 -> -2711.9739 | H17: =-Calcs!H60 -> -2772.9933 | I17: =-Calcs!I60 -> -2835.3856 | J17: =-Calcs!J60 -> -2899.1818 | K17: =-Calcs!K60 -> -2964.4134 | ... S17: =-Calcs!S60 -> -3541.9734
B18: Total Costs | C18: [£'000] | D18: =SUM(D16:D17) -> -3125 | E18: =SUM(E16:E17) -> -3210.9375 | F18: =SUM(F16:F17) -> -3299.2383 | G18: =SUM(G16:G17) -> -3389.9673 | H18: =SUM(H16:H17) -> -3466.2416 | I18: =SUM(I16:I17) -> -3544.232 | J18: =SUM(J16:J17) -> -3623.9773 | K18: =SUM(K16:K17) -> -3705.5167 | ... S18: =SUM(S16:S17) -> -4427.4668
B20: EBITDA | C20: [£'000] | D20: =SUM(D14,D18) -> 8750 | E20: =SUM(E14,E18) -> 8850.8784 | F20: =SUM(F14,F18) -> 8917.2135 | G20: =SUM(G14,G18) -> 8947.5974 | H20: =SUM(H14,H18) -> 8897.0806 | I20: =SUM(I14,I18) -> 8809.9226 | J20: =SUM(J14,J18) -> 8686.7658 | K20: =SUM(K14,K18) -> 8528.7406 | ... S20: =SUM(S14,S18) -> 803.14112
B21: Margin | C21: [%] | D21: =IF(D14=0,0,D20/D14) -> 0.73684211 | E21: =IF(E14=0,0,E20/E14) -> 0.73379319 | F21: =IF(F14=0,0,F20/F14) -> 0.72993482 | G21: =IF(G14=0,0,G20/G14) -> 0.72523205 | H21: =IF(H14=0,0,H20/H14) -> 0.7196351 | I21: =IF(I14=0,0,I20/I14) -> 0.71311416 | J21: =IF(J14=0,0,J20/J14) -> 0.70562482 | K21: =IF(K14=0,0,K20/K14) -> 0.6971196 | ... S21: =IF(S14=0,0,S20/S14) -> 0.15354642
B23: Depreciation | C23: [£'000] | E23: =-Calcs!E67 -> -4500 | F23: =-Calcs!F67 -> -4500 | G23: =-Calcs!G67 -> -4500 | H23: =-Calcs!H67 -> -4500 | I23: =-Calcs!I67 -> -4500 | J23: =-Calcs!J67 -> -4500 | K23: =-Calcs!K67 -> -4500 | L23: =-Calcs!L67 -> -4500 | ... S23: =-Calcs!S67 -> -4500
B24: EBIT | C24: [£'000] | E24: =E20+E23 -> 4350.8784 | F24: =F20+F23 -> 4417.2135 | G24: =G20+G23 -> 4447.5974 | H24: =H20+H23 -> 4397.0806 | I24: =I20+I23 -> 4309.9226 | J24: =J20+J23 -> 4186.7658 | K24: =K20+K23 -> 4028.7406 | L24: =L20+L23 -> 4375.9078 | ... S24: =S20+S23 -> -3696.8589
B26: Interest & Financing Costs | C26: [£'000] | E26: =-Calcs!E131 -> -2064.9084 | F26: =-Calcs!F131 -> -1935.776 | G26: =-Calcs!G131 -> -1893.4483 | H26: =-Calcs!H131 -> -1848.3257 | I26: =-Calcs!I131 -> -1761.5959 | J26: =-Calcs!J131 -> -1598.613 | K26: =-Calcs!K131 -> -1379.3092 | L26: =-Calcs!L131 -> -1142.0819 | ... S26: =-Calcs!S131 -> 0
B27: Profit Before Tax | C27: [£'000] | E27: =E24+E26 -> 2285.97 | F27: =F24+F26 -> 2481.4375 | G27: =G24+G26 -> 2554.1491 | H27: =H24+H26 -> 2548.7549 | I27: =I24+I26 -> 2548.3266 | J27: =J24+J26 -> 2588.1528 | K27: =K24+K26 -> 2649.4314 | L27: =L24+L26 -> 3233.8259 | ... S27: =S24+S26 -> -3696.8589
B28: Tax | C28: [£'000] | E28: =-Calcs!E145 -> -571.4925 | F28: =-Calcs!F145 -> -620.35938 | G28: =-Calcs!G145 -> -638.53727 | H28: =-Calcs!H145 -> -637.18873 | I28: =-Calcs!I145 -> -637.08166 | J28: =-Calcs!J145 -> -647.0382 | K28: =-Calcs!K145 -> -662.35786 | L28: =-Calcs!L145 -> -808.45647 | ... S28: =-Calcs!S145 -> 0
B29: Net Income | C29: [£'000] | E29: =E27+E28 -> 1714.4775 | F29: =F27+F28 -> 1861.0781 | G29: =G27+G28 -> 1915.6118 | H29: =H27+H28 -> 1911.5662 | I29: =I27+I28 -> 1911.245 | J29: =J27+J28 -> 1941.1146 | K29: =K27+K28 -> 1987.0736 | L29: =L27+L28 -> 2425.3694 | ... S29: =S27+S28 -> -3696.8589
A33: =MAX($A$2:A32)+0.01 -> 3.02 | B33: Cashflow
B35: EBITDA | C35: [£'000] | E35: =E20 -> 8850.8784 | F35: =F20 -> 8917.2135 | G35: =G20 -> 8947.5974 | H35: =H20 -> 8897.0806 | I35: =I20 -> 8809.9226 | J35: =J20 -> 8686.7658 | K35: =K20 -> 8528.7406 | L35: =L20 -> 8875.9078 | ... S35: =S20 -> 803.14112
B36: Working Capital | C36: [£'000] | E36: =Calcs!E79 -> -10.62824 | F36: =Calcs!F79 -> -7.1494876 | G36: =Calcs!G79 -> -3.5287882 | H36: =Calcs!H79 -> 4.7194638 | I36: =Calcs!I79 -> 8.4134957 | J36: =Calcs!J79 -> 12.042387 | K36: =Calcs!K79 -> 15.556877 | L36: =Calcs!L79 -> -35.503414 | ... S36: =Calcs!S79 -> 37.854034
B37: Tax Paid | C37: [£'000] | E37: =-Calcs!E145 -> -571.4925 | F37: =-Calcs!F145 -> -620.35938 | G37: =-Calcs!G145 -> -638.53727 | H37: =-Calcs!H145 -> -637.18873 | I37: =-Calcs!I145 -> -637.08166 | J37: =-Calcs!J145 -> -647.0382 | K37: =-Calcs!K145 -> -662.35786 | L37: =-Calcs!L145 -> -808.45647 | ... S37: =-Calcs!S145 -> 0
B38: CFADS | C38: [£'000] | E38: =SUM(E35:E37) -> 8268.7577 | F38: =SUM(F35:F37) -> 8289.7047 | G38: =SUM(G35:G37) -> 8305.5313 | H38: =SUM(H35:H37) -> 8264.6114 | I38: =SUM(I35:I37) -> 8181.2544 | J38: =SUM(J35:J37) -> 8051.77 | K38: =SUM(K35:K37) -> 7881.9396 | L38: =SUM(L35:L37) -> 8031.9479 | ... S38: =SUM(S35:S37) -> 840.99515
B40: Senior Interest | C40: [£'000] | E40: =-Calcs!E103 -> -1979.5043 | F40: =-Calcs!F103 -> -1850.3719 | G40: =-Calcs!G103 -> -1808.0442 | H40: =-Calcs!H103 -> -1762.9216 | I40: =-Calcs!I103 -> -1676.1918 | J40: =-Calcs!J103 -> -1513.2089 | K40: =-Calcs!K103 -> -1293.905 | L40: =-Calcs!L103 -> -1056.6778 | ... S40: =-Calcs!S103 -> 0
B41: Senior Principal Repayment | C41: [£'000] | E41: =-Calcs!E105 -> -4381.0785 | F41: =-Calcs!F105 -> -4526.324 | G41: =-Calcs!G105 -> -4580.8261 | H41: =-Calcs!H105 -> -4594.4718 | I41: =-Calcs!I105 -> -4617.0808 | J41: =-Calcs!J105 -> -4680.4603 | K41: =-Calcs!K105 -> -4769.1254 | L41: =-Calcs!L105 -> -5121.7437 | ... S41: =-Calcs!S105 -> 0
B42: Total Senior Debt Service | C42: [£'000] | E42: =SUM(E40:E41) -> -6360.5828 | F42: =SUM(F40:F41) -> -6376.6959 | G42: =SUM(G40:G41) -> -6388.8702 | H42: =SUM(H40:H41) -> -6357.3934 | I42: =SUM(I40:I41) -> -6293.2726 | J42: =SUM(J40:J41) -> -6193.6693 | K42: =SUM(K40:K41) -> -6063.0305 | L42: =SUM(L40:L41) -> -6178.4214 | ... S42: =SUM(S40:S41) -> 0
B43: DSCR | C43: [x] | E43: =IF(E42=0,"n/a",-E38/E42) -> 1.3 | F43: =IF(F42=0,"n/a",-F38/F42) -> 1.3 | G43: =IF(G42=0,"n/a",-G38/G42) -> 1.3 | H43: =IF(H42=0,"n/a",-H38/H42) -> 1.3 | I43: =IF(I42=0,"n/a",-I38/I42) -> 1.3 | J43: =IF(J42=0,"n/a",-J38/J42) -> 1.3 | K43: =IF(K42=0,"n/a",-K38/K42) -> 1.3 | L43: =IF(L42=0,"n/a",-L38/L42) -> 1.3 | ... S43: =IF(S42=0,"n/a",-S38/S42) -> n/a
B45: Release of Opening Cash Balance | C45: [£'000] | E45: =$D$74 -> 3500 | F45: 0 | G45: 0 | H45: 0 | I45: 0 | J45: 0 | K45: 0 | L45: 0 | M45: 0 | N45: 0 | O45: 0 | P45: 0 | Q45: 0 | R45: 0 | S45: 0
B46: Net Cashflows to Equity | C46: [£'000] | E46: =E38+E42+E45 -> 5408.1748 | F46: =F38+F42+F45 -> 1913.0088 | G46: =G38+G42+G45 -> 1916.6611 | H46: =H38+H42+H45 -> 1907.218 | I46: =I38+I42+I45 -> 1887.9818 | J46: =J38+J42+J45 -> 1858.1008 | K46: =K38+K42+K45 -> 1818.9091 | L46: =L38+L42+L45 -> 1853.5264 | ... S46: =S38+S42+S45 -> 840.99515
B47: Equity Cash Flow (incl. day-one investment) | C47: [£'000] | D47: =-D56 -> -14799.873 | E47: =E46 -> 5408.1748 | F47: =F46 -> 1913.0088 | G47: =G46 -> 1916.6611 | H47: =H46 -> 1907.218 | I47: =I46 -> 1887.9818 | J47: =J46 -> 1858.1008 | K47: =K46 -> 1818.9091 | L47: =L46 -> 1853.5264 | ... S47: =S46 -> 840.99515
A49: =MAX($A$2:A47)+0.01 -> 3.03 | B49: Valuation
B51: Buy and Hold
B52: Equity Purchase Price payable to Vendor | C52: [£'000] | D52: =NPV(Assumptions!$D$93,E46:S46)+Calcs!$D$98-Calcs!$D$99-Assumptions!$D$92 -> 64517.503
B53: Transaction Costs | C53: [£'000] | D53: =Assumptions!$D$92 -> 500
B54: Upfront Debt Fee | C54: [£'000] | D54: =Calcs!$D$99 -> 1024.8496
B55: Less: Senior Debt Drawn | C55: [£'000] | D55: =-Calcs!$D$98 -> -51242.479
B56: Investor Equity Investment | C56: [£'000] | D56: =SUM(D52:D55) -> 14799.873
B57: IRR | C57: [%] | D57: =IRR(D47:S47) -> 0.12
...

Sheet Analysis
A2: =Output!A2+1 -> 4 | B2: Project Storm - Key Results and Supporting Analysis
B4: Period End | D4: =Output!D4 -> 41274 | E4: =Output!E4 -> 41639 | F4: =Output!F4 -> 42004 | G4: =Output!G4 -> 42369 | H4: =Output!H4 -> 42735 | I4: =Output!I4 -> 43100 | J4: =Output!J4 -> 43465 | K4: =Output!K4 -> 43830 | ... S4: =Output!S4 -> 46752
B5: Calendar Year | D5: =YEAR(D4) -> 2012 | E5: =YEAR(E4) -> 2013 | F5: =YEAR(F4) -> 2014 | G5: =YEAR(G4) -> 2015 | H5: =YEAR(H4) -> 2016 | I5: =YEAR(I4) -> 2017 | J5: =YEAR(J4) -> 2018 | K5: =YEAR(K4) -> 2019 | ... S5: =YEAR(S4) -> 2027
B6: Model Year | D6: 0 | E6: =D6+1 -> 1 | F6: =E6+1 -> 2 | G6: =F6+1 -> 3 | H6: =G6+1 -> 4 | I6: =H6+1 -> 5 | J6: =I6+1 -> 6 | K6: =J6+1 -> 7 | L6: =K6+1 -> 8 | ... S6: =R6+1 -> 15
A8: =MAX($A$2:A7)+0.01 -> 4.01 | B8: Summary of Results
B10: Recommended bid price - equity value to vendor | C10: [£'000] | D10: =Output!$D$52 -> 64517.503
B11: Implied enterprise value | C11: [£'000] | D11: =Output!$D$59 -> 61017.503
B12: Enterprise value per MW | C12: [£'000/MW] | D12: =D11/Assumptions!$D$47 -> 1220.3501
B13: Senior debt sized | C13: [£'000] | D13: =Calcs!$D$98 -> 51242.479
B14: Investor equity cheque | C14: [£'000] | D14: =Output!$D$56 -> 14799.873
B15: Buy & hold equity IRR | C15: [%] | D15: =Output!$D$57 -> 0.12
B17: Downside: equity IRR - P90 for 10 years, then P75 | C17: [%] | D17: =$D$75 -> 0.068863578
B18: Minimum DSCR in that scenario | C18: [x] | D18: =$D$76 -> 1.2102096
B20: Exit: investor IRR on a 2-year hold, exit priced at 11% | C20: [%] | D20: =$D$90 -> 0.13195321
B21: Net equity proceeds at exit | C21: [£'000] | D21: =Output!$D$68 -> 10928.536
B23: Hedging: 12-year amortising swap rate | C23: [%] | D23: =$D$103 -> 0.016381739
B24: All-in fixed cost of debt (swap + margin) | C24: [%] | D24: =$D$104 -> 0.046381739
B26: Tax: impact of the 30% interest cap on the bid price | C26: [£'000] | D26: =$D$120 -> 0
B27: Minimum headroom under the cap | C27: [£'000] | D27: =$D$116 -> 388.26254
B29: Sub-debt: subordinated loan sized | C29: [£'000] | D29: =$D$131 -> 6226.7708
B30: Investor equity IRR with subordinated loan | C30: [%] | D30: =$D$168 -> 0.13948891
B31: Uplift versus the base case | C31: [bps] | D31: =($D$168-Output!$D$57)*10000 -> 194.88907
B33: The PPA analysis is on the "Sensitivities" sheet and discussed in the valuation memo.
A35: =MAX($A$2:A34)+0.01 -> 4.02 | B35: Downside case - P90 for the first 10 years, P75 thereafter
B37: Production | C37: [GWh] | D37: =Calcs!D15 -> 125 | E37: =IF(E$5<=$D$5+10,Calcs!E16,Calcs!E15) -> 117.5 | F37: =IF(F$5<=$D$5+10,Calcs!F16,Calcs!F15) -> 117.5 | G37: =IF(G$5<=$D$5+10,Calcs!G16,Calcs!G15) -> 117.5 | H37: =IF(H$5<=$D$5+10,Calcs!H16,Calcs!H15) -> 117.5 | I37: =IF(I$5<=$D$5+10,Calcs!I16,Calcs!I15) -> 117.5 | J37: =IF(J$5<=$D$5+10,Calcs!J16,Calcs!J15) -> 117.5 | K37: =IF(K$5<=$D$5+10,Calcs!K16,Calcs!K15) -> 117.5 | L37: =IF(L$5<=$D$5+10,Calcs!L16,Calcs!L15) -> 117.5 | ... S37: =IF(S$5<=$D$5+10,Calcs!S16,Calcs!S15) -> 125
B39: Revenue from Electricity | C39: [£'000] | D39: =D37*Calcs!D49 -> 6875 | E39: =E37*Calcs!E49 -> 6591.107 | F39: =F37*Calcs!F49 -> 6688.9947 | G39: =G37*Calcs!G49 -> 6754.8961 | H39: =H37*Calcs!H49 -> 6754.8961 | I39: =I37*Calcs!I49 -> 6721.9454 | J39: =J37*Calcs!J49 -> 6656.6838 | K39: =K37*Calcs!K49 -> 6560.2101 | ... S39: =S37*Calcs!S49 -> 5230.6079
B40: Revenue from Subsidy | C40: [£'000] | D40: =D37*Calcs!D50 -> 5000 | E40: =E37*Calcs!E50 -> 4747 | F40: =F37*Calcs!F50 -> 4794.47 | G40: =G37*Calcs!G50 -> 4842.4147 | H40: =H37*Calcs!H50 -> 4866.6268 | I40: =I37*Calcs!I50 -> 4890.9599 | J40: =J37*Calcs!J50 -> 4915.4147 | K40: =K37*Calcs!K50 -> 4939.9918 | ... S40: =S37*Calcs!S50 -> 0
B41: Total Revenue | C41: [£'000] | D41: =SUM(D39:D40) -> 11875 | E41: =SUM(E39:E40) -> 11338.107 | F41: =SUM(F39:F40) -> 11483.465 | G41: =SUM(G39:G40) -> 11597.311 | H41: =SUM(H39:H40) -> 11621.523 | I41: =SUM(I39:I40) -> 11612.905 | J41: =SUM(J39:J40) -> 11572.099 | K41: =SUM(K39:K40) -> 11500.202 | ... S41: =SUM(S39:S40) -> 5230.6079
B42: Fixed Costs | C42: [£'000] | D42: =Calcs!D60 -> 2500 | E42: =Calcs!E60 -> 2568.75 | F42: =Calcs!F60 -> 2639.3906 | G42: =Calcs!G60 -> 2711.9739 | H42: =Calcs!H60 -> 2772.9933 | I42: =Calcs!I60 -> 2835.3856 | J42: =Calcs!J60 -> 2899.1818 | K42: =Calcs!K60 -> 2964.4134 | ... S42: =Calcs!S60 -> 3541.9734
B43: Variable Costs | C43: [£'000] | D43: =Assumptions!$D$63*D37*Calcs!D9 -> 625 | E43: =Assumptions!$D$63*E37*Calcs!E9 -> 603.65625 | F43: =Assumptions!$D$63*F37*Calcs!F9 -> 620.2568 | G43: =Assumptions!$D$63*G37*Calcs!G9 -> 637.31386 | H43: =Assumptions!$D$63*H37*Calcs!H9 -> 651.65342 | I43: =Assumptions!$D$63*I37*Calcs!I9 -> 666.31562 | J43: =Assumptions!$D$63*J37*Calcs!J9 -> 681.30772 | K43: =Assumptions!$D$63*K37*Calcs!K9 -> 696.63715 | ... S43: =Assumptions!$D$63*S37*Calcs!S9 -> 885.49336
B44: Total Operating Costs | C44: [£'000] | D44: =SUM(D42:D43) -> 3125 | E44: =SUM(E42:E43) -> 3172.4062 | F44: =SUM(F42:F43) -> 3259.6474 | G44: =SUM(G42:G43) -> 3349.2877 | H44: =SUM(H42:H43) -> 3424.6467 | I44: =SUM(I42:I43) -> 3501.7013 | J44: =SUM(J42:J43) -> 3580.4895 | K44: =SUM(K42:K43) -> 3661.0505 | ... S44: =SUM(S42:S43) -> 4427.4668
B46: EBITDA | C46: [£'000] | D46: =D41-D44 -> 8750 | E46: =E41-E44 -> 8165.7007 | F46: =F41-F44 -> 8223.8173 | G46: =G41-G44 -> 8248.0231 | H46: =H41-H44 -> 8196.8762 | I46: =I41-I44 -> 8111.2041 | J46: =J41-J44 -> 7991.609 | K46: =K41-K44 -> 7839.1514 | ... S46: =S41-S44 -> 803.14112
B47: Depreciation | C47: [£'000] | E47: =Calcs!E67 -> 4500 | F47: =Calcs!F67 -> 4500 | G47: =Calcs!G67 -> 4500 | H47: =Calcs!H67 -> 4500 | I47: =Calcs!I67 -> 4500 | J47: =Calcs!J67 -> 4500 | K47: =Calcs!K67 -> 4500 | L47: =Calcs!L67 -> 4500 | ... S47: =Calcs!S67 -> 4500
B49: Financing Costs (senior debt already committed) | C49: [£'000] | E49: =Calcs!E131 -> 2064.9084 | F49: =Calcs!F131 -> 1935.776 | G49: =Calcs!G131 -> 1893.4483 | H49: =Calcs!H131 -> 1848.3257 | I49: =Calcs!I131 -> 1761.5959 | J49: =Calcs!J131 -> 1598.613 | K49: =Calcs!K131 -> 1379.3092 | L49: =Calcs!L131 -> 1142.0819 | ... S49: =Calcs!S131 -> 0
B50: Interest Cap (30% of EBITDA) | C50: [£'000] | E50: =Assumptions!$D$70*MAX(E46,0) -> 2449.7102 | F50: =Assumptions!$D$70*MAX(F46,0) -> 2467.1452 | G50: =Assumptions!$D$70*MAX(G46,0) -> 2474.4069 | H50: =Assumptions!$D$70*MAX(H46,0) -> 2459.0629 | I50: =Assumptions!$D$70*MAX(I46,0) -> 2433.3612 | J50: =Assumptions!$D$70*MAX(J46,0) -> 2397.4827 | K50: =Assumptions!$D$70*MAX(K46,0) -> 2351.7454 | L50: =Assumptions!$D$70*MAX(L46,0) -> 2448.446 | ... S50: =Assumptions!$D$70*MAX(S46,0) -> 240.94233
B51: Disallowed Interest b/f | C51: [£'000] | E51: =D54 -> 0 | F51: =E54 -> 0 | G51: =F54 -> 0 | H51: =G54 -> 0 | I51: =H54 -> 0 | J51: =I54 -> 0 | K51: =J54 -> 0 | L51: =K54 -> 0 | ... S51: =R54 -> 0
B52: Allowed - Current Year | C52: [£'000] | E52: =MIN(E49,E50) -> 2064.9084 | F52: =MIN(F49,F50) -> 1935.776 | G52: =MIN(G49,G50) -> 1893.4483 | H52: =MIN(H49,H50) -> 1848.3257 | I52: =MIN(I49,I50) -> 1761.5959 | J52: =MIN(J49,J50) -> 1598.613 | K52: =MIN(K49,K50) -> 1379.3092 | L52: =MIN(L49,L50) -> 1142.0819 | ... S52: =MIN(S49,S50) -> 0
B53: Utilisation of b/f Disallowed Interest | C53: [£'000] | E53: =MIN(E51,MAX(E50-E49,0)) -> 0 | F53: =MIN(F51,MAX(F50-F49,0)) -> 0 | G53: =MIN(G51,MAX(G50-G49,0)) -> 0 | H53: =MIN(H51,MAX(H50-H49,0)) -> 0 | I53: =MIN(I51,MAX(I50-I49,0)) -> 0 | J53: =MIN(J51,MAX(J50-J49,0)) -> 0 | K53: =MIN(K51,MAX(K50-K49,0)) -> 0 | L53: =MIN(L51,MAX(L50-L49,0)) -> 0 | ... S53: =MIN(S51,MAX(S50-S49,0)) -> 0
B54: Disallowed Interest c/f | C54: [£'000] | D54: 0 | E54: =E51+MAX(E49-E50,0)-E53 -> 0 | F54: =F51+MAX(F49-F50,0)-F53 -> 0 | G54: =G51+MAX(G49-G50,0)-G53 -> 0 | H54: =H51+MAX(H49-H50,0)-H53 -> 0 | I54: =I51+MAX(I49-I50,0)-I53 -> 0 | J54: =J51+MAX(J49-J50,0)-J53 -> 0 | K54: =K51+MAX(K49-K50,0)-K53 -> 0 | L54: =L51+MAX(L49-L50,0)-L53 -> 0 | ... S54: =S51+MAX(S49-S50,0)-S53 -> 0
B55: Total Interest Allowed | C55: [£'000] | E55: =E52+E53 -> 2064.9084 | F55: =F52+F53 -> 1935.776 | G55: =G52+G53 -> 1893.4483 | H55: =H52+H53 -> 1848.3257 | I55: =I52+I53 -> 1761.5959 | J55: =J52+J53 -> 1598.613 | K55: =K52+K53 -> 1379.3092 | L55: =L52+L53 -> 1142.0819 | ... S55: =S52+S53 -> 0
...

Sheet Sensitivities
A2: =Analysis!A2+1 -> 5 | B2: Project Storm - Sensitivities & Supporting Analysis
A4: =MAX($A$2:A3)+0.01 -> 5.01 | B4: Bid Price versus Target Equity Return [live]
B6: Target Equity IRR | C6: Equity Cheque | D6: Bid Price (equity) | E6: Implied EV | F6: EV per MW
B7: 0.1 | C7: =NPV($B7,Output!$E$46:$S$46) -> 16054.778 | D7: =C7+Calcs!$D$98-Calcs!$D$99-Assumptions!$D$92 -> 65772.407 | E7: =D7-Output!$D$74 -> 62272.407 | F7: =E7/Assumptions!$D$47 -> 1245.4481
B8: 0.105 | C8: =NPV($B8,Output!$E$46:$S$46) -> 15722.537 | D8: =C8+Calcs!$D$98-Calcs!$D$99-Assumptions!$D$92 -> 65440.166 | E8: =D8-Output!$D$74 -> 61940.166 | F8: =E8/Assumptions!$D$47 -> 1238.8033
B9: 0.11 | C9: =NPV($B9,Output!$E$46:$S$46) -> 15403.061 | D9: =C9+Calcs!$D$98-Calcs!$D$99-Assumptions!$D$92 -> 65120.69 | E9: =D9-Output!$D$74 -> 61620.69 | F9: =E9/Assumptions!$D$47 -> 1232.4138
B10: 0.115 | C10: =NPV($B10,Output!$E$46:$S$46) -> 15095.708 | D10: =C10+Calcs!$D$98-Calcs!$D$99-Assumptions!$D$92 -> 64813.337 | E10: =D10-Output!$D$74 -> 61313.337 | F10: =E10/Assumptions!$D$47 -> 1226.2667
B11: 0.12 | C11: =NPV($B11,Output!$E$46:$S$46) -> 14799.873 | D11: =C11+Calcs!$D$98-Calcs!$D$99-Assumptions!$D$92 -> 64517.503 | E11: =D11-Output!$D$74 -> 61017.503 | F11: =E11/Assumptions!$D$47 -> 1220.3501
B12: 0.125 | C12: =NPV($B12,Output!$E$46:$S$46) -> 14514.99 | D12: =C12+Calcs!$D$98-Calcs!$D$99-Assumptions!$D$92 -> 64232.619 | E12: =D12-Output!$D$74 -> 60732.619 | F12: =E12/Assumptions!$D$47 -> 1214.6524
B13: 0.13 | C13: =NPV($B13,Output!$E$46:$S$46) -> 14240.52 | D13: =C13+Calcs!$D$98-Calcs!$D$99-Assumptions!$D$92 -> 63958.15 | E13: =D13-Output!$D$74 -> 60458.15 | F13: =E13/Assumptions!$D$47 -> 1209.163
B14: 0.14 | C14: =NPV($B14,Output!$E$46:$S$46) -> 13720.838 | D14: =C14+Calcs!$D$98-Calcs!$D$99-Assumptions!$D$92 -> 63438.468 | E14: =D14-Output!$D$74 -> 59938.468 | F14: =E14/Assumptions!$D$47 -> 1198.7694
B16: The bid price barely moves across a 400bp range of target returns: only c.£2.3m separates a 10% and a 14% hurdle. Because the equity cheque is a thin slice of the price, discipline on debt sizing matters far more than discipline on the hurdle rate.
A19: =MAX($A$2:A18)+0.01 -> 5.02 | B19: Equity IRR at the Recommended Price - Operating Scenarios
B21: Scenario | C21: Equity IRR | D21: Minimum DSCR | E21: How to reproduce
B22: Base case (P75, base power price) | C22: 0.12 | D22: 1.3 | E22: Assumptions!D50 = 1
B23: P90 for 10 years, then P75 | C23: 0.0689 | D23: 1.21 | E23: Assumptions!D50 = 3
B24: P90 in every year | C24: 0.0595 | D24: 1.09 | E24: Assumptions!D50 = 2
B25: Power price -5% | C25: 0.0867 | D25: 1.1 | E25: Scale Calcs row 49 by 0.95
B26: Power price -10% | C26: 0.0476 | D26: 0.89 | E26: Scale Calcs row 49 by 0.90
B27: Power price +10% | C27: 0.1773 | D27: 1.37 | E27: Scale Calcs row 49 by 1.10
B28: Operating costs +10% | C28: 0.0833 | D28: 1.02 | E28: Assumptions!D62 = 55, D63 = 5.5
B29: Power price -10% and P90 throughout | C29: -0.0349 | D29: 0.7 | E29: Both of the above
B31: Values are produced by flexing the input cells named in the final column and reading Output!D57 and the DSCR row. They are pasted here as inputs so that the whole grid can be seen at once.
B32: Read-across: at 84% gearing the equity is highly geared to the power price. A 10% price shortfall alone takes DSCR below 1.00x - a payment default, not merely a covenant breach.
A35: =MAX($A$2:A34)+0.01 -> 5.03 | B35: Bid Price at Tighter Interest Deductibility Caps
B37: Cap (% of EBITDA) | C37: Senior Debt | D37: Bid Price | E37: Change vs Base
B38: No limit | C38: 51242 | D38: 64518 | E38: 0
B39: 30% (base assumption) | C39: 51242 | D39: 64518 | E39: 0
B40: 25% | C40: 51242 | D40: 64518 | E40: 0
B41: 20% | C41: 51222 | D41: 64485 | E41: -32
B42: 15% | C42: 50856 | D42: 64032 | E42: -486
B43: 10% | C43: 50190 | D43: 63236 | E43: -1281
B44: 5% | C44: 49525 | D44: 62441 | E44: -2077
B45: Nil deduction | C45: 48859 | D45: 61646 | E45: -2872
B47: The 30% cap is worth nothing at this leverage. It would only start to bite at roughly £65.9m of senior debt - about 98% of fixed assets - which the DSCR test rules out long before the tax rule does.
A50: =MAX($A$2:A49)+0.01 -> 5.04 | B50: Financial Impact of a PPA
B52: A fixed-price PPA on the merchant element, priced at a discount to the forward curve, in exchange for a lower DSCR floor from the banks.
B54: Bid price at a 12% equity IRR
B55: PPA discount to the curve | C55: DSCR floor 1.30x (merchant) | D55: DSCR floor 1.20x | E55: DSCR floor 1.15x
B56: 0% (curve) | C56: 64518 | D56: 65926 | E56: 66438
...
